Workbook

Sheet 見積内訳書
L1: お客様名
L2: 浅野誠一郎
L3: 工事場所入力
L5: 見積有効期限
L7: 見積有効期限
L9: 担当者
L12: 横自由入力
K13: ←
L16: 変更禁止 ↓↓
L17: 会社 情報
L18: ラグズ建築
L19: 〒500-8388
L20: 岐阜県岐阜市今嶺４丁目５−２０
E33: 内 訳 明 細 書 | J33: 1 | K33: 日付 | L33: 担当者 | S33: / | U33: ※下記二十枠部分触るな！
A35: 名 称 | E35: 数量 | F35: 呼称 | G35: 単 価 | H35: 金 額 | I35: 定価 | J35: 備 考 | K35: 職人 | L35: 人工 | M35: 人当 | N35: 費用 | O35: 材料 | P35: 数量 | Q35: Net | R35: 費用 | S35: 原価 | T35: 粗利率 | U35: 材料
N36: =L36*M36 -> 0 | R36: =P36*Q36 -> 0 | S36: =N36+R36 -> 0 | T36: =IF(H36<>0,1-(S36/H36),0) -> 0 | U36: 養生 | V36: =BD368 -> 0 | W36: =BE368 -> 0
A37: 1 | B37: 仮設工事 | E37: 1 | F37: 式 | H37: =H82 -> 0 | O37: 粗利率３５％（税抜） | R37: =B37 -> 仮設工事 | S37: =S82 -> 0 | T37: =IF(H37<>0,1-(S37/H37),0) -> 0 | U37: 産廃 | V37: =BF368 -> 0 | W37: =BG368 -> 0
A38: 2 | E38: 1 | F38: 式 | H38: =H108 -> 0 | O38: =SUM(K41/0.65) -> 0 | R38: =B38 -> 0 | S38: =S108 -> 0 | T38: =IF(H38<>0,1-(S38/H38),0) -> 0 | U38: 材木 | V38: =BH368 -> 1 | W38: =BI368 -> 0
A39: 3 | E39: 1 | F39: 式 | H39: =H134 -> 0 | R39: =B39 -> 0 | S39: =S134 -> 0 | T39: =IF(H39<>0,1-(S39/H39),0) -> 0 | U39: 建材 | V39: =BJ368 -> 0 | W39: =BK368 -> 0
A40: 4 | E40: 1 | F40: 式 | H40: =H160 -> 0 | K40: 原価 | O40: 粗利率３５％（税込） | R40: =B40 -> 0 | S40: =S160 -> 0 | T40: =IF(H40<>0,1-(S40/H40),0) -> 0 | U40: 電材 | V40: =BL368 -> 0 | W40: =BM368 -> 0
A41: 5 | E41: 1 | F41: 式 | H41: =H186 -> 0 | K41: =SUM(S55,K38) -> 0 | O41: =SUM(O38*1.1) -> 0 | R41: =B41 -> 0 | S41: =S186 -> 0 | T41: =IF(H41<>0,1-(S41/H41),0) -> 0 | U41: 住設 | V41: =BN368 -> 0 | W41: =BO368 -> 0
A42: 6 | E42: 1 | F42: 式 | H42: =H212 -> 0 | R42: =B42 -> 0 | S42: =S212 -> 0 | T42: =IF(H42<>0,1-(S42/H42),0) -> 0 | U42: サッシ | V42: =BP368 -> 0 | W42: =BQ368 -> 0
A43: 7 | E43: 1 | F43: 式 | H43: =H238 -> 0 | K43: 諸経費別 合計 | O43: 見積時税抜き粗利高 | R43: =B43 -> 0 | S43: =S238 -> 0 | T43: =IF(H43<>0,1-(S43/H43),0) -> 0 | U43: 足場 | V43: =BR368 -> 0 | W43: =BS368 -> 0
A44: 8 | E44: 1 | F44: 式 | H44: =H264 -> 0 | K44: =SUM(H37:H49) -> 0 | O44: =H54-S55 -> 0 | R44: =B44 -> 0 | S44: =S264 -> 0 | T44: =IF(H44<>0,1-(S44/H44),0) -> 0 | U44: 外壁 | V44: =BT368 -> 0 | W44: =BU368 -> 0
A45: 9 | E45: 1 | F45: 式 | H45: =H290 -> 0 | R45: =B45 -> 0 | S45: =S290 -> 0 | T45: =IF(H45<>0,1-(S45/H45),0) -> 0 | U45: 外構 | V45: =BV368 -> 0 | W45: =BW368 -> 0
A46: 10 | E46: 1 | F46: 式 | H46: =H316 -> 0 | K46: 粗利率（％） | R46: =B46 -> 0 | S46: =S316 -> 0 | T46: =IF(H46<>0,1-(S46/H46),0) -> 0 | U46: 雑費 | V46: =BX368 -> 0 | W46: =BY368 -> 0
A47: 11 | E47: 1 | F47: 式 | H47: =H342 -> 0 | K47: =SUM(1-K41/H54) -> #DIV/0! | R47: =B47 -> 0 | S47: =S342 -> 0 | T47: =IF(H47<>0,1-(S47/H47),0) -> 0 | U47: ガス | V47: =BZ368 -> 0 | W47: =CA368 -> 0
H48: =H368 -> 0 | N48: ※下記二十枠部分触るな！ | R48: =B48 -> 0 | S48: =S368 -> 0 | T48: =IF(H48<>0,1-(S48/H48),0) -> 0 | U48: ラグズ | V48: =CB368 -> 0 | W48: =CC368 -> 0
K49: 解体 | L49: =V368 -> 0 | M49: =W368 -> 0 | N49: 仮設 | O49: =AN368 -> 0 | P49: =AO368 -> 0 | R49: =B49 -> 0 | T49: =IF(H49<>0,1-(S49/H49),0) -> 0 | U49: 解体 | V49: =CD368 -> 0 | W49: =CE368 -> 0
K50: 設備 | L50: =X368 -> 0 | M50: =Y368 -> 0 | N50: 養生 | O50: =AP368 -> 0 | P50: =AQ368 -> 0 | T50: =IF(H50<>0,1-(S50/H50),0) -> 0 | U50: 大工 | V50: =CF368 -> 0 | W50: =CG368 -> 0
K51: 電気 | L51: =Z368 -> 0 | M51: =AA368 -> 0 | N51: 足場 | O51: =AR368 -> 0 | P51: =AS368 -> 0 | R51: =B51 -> 0 | T51: =IF(H51<>0,1-(S51/H51),0) -> 0 | U51: 電気 | V51: =CH368 -> 0 | W51: =CI368 -> 0
B52: 諸 経 費 | H52: =K44*0.08 -> 0 | K52: ガス | L52: =AB368 -> 0 | M52: =AC368 -> 0 | N52: 板金 | O52: =AT368 -> 0 | P52: =AU368 -> 0 | R52: ヨビ | S52: =H54*0.03 -> 0 | U52: 設備 | V52: =CJ368 -> 0 | W52: =CK368 -> 0
B53: 端 数 値 引 | K53: 大工 | L53: =AD368 -> 0 | M53: =AE368 -> 0 | N53: 屋根 | O53: =AV368 -> 0 | P53: =AW368 -> 0 | R53: =B53 -> 端 数 値 引 | T53: =IF(H53<>0,1-(S53/H53),0) -> 0 | U53: クロス | V53: =CL368 -> 0 | W53: =CM368 -> 0
B54: 合 計 | G54: =SUM(G37:G53) -> 0 | H54: =SUM(H37:H53) -> 0 | K54: クロス | L54: =AF368 -> 0 | M54: =AG368 -> 0 | N54: 塗装 | O54: =AX368 -> 0 | P54: =AY368 -> 0 | T54: =IF(H54<>0,1-(S54/H54),0) -> 0 | U54: 左官 | V54: =CN368 -> 0 | W54: =CO368 -> 0
B55: 消 費 税 | D55: 0.1 | G55: =G54*0.05 -> 0 | H55: =H54*10% -> 0 | K55: 左官 | L55: =AH368 -> 0 | M55: =AI368 -> 0 | N55: 建具 | O55: =AZ368 -> 0 | P55: =BA368 -> 0 | Q55: ゴミ経費なし 原価 | R55: 小計 | S55: =SUM(S37:S54) -> 0 | U55: 清掃 | V55: =CP368 -> 0 | W55: =CQ368 -> 0
K56: 清掃 | L56: =AJ368 -> 0 | M56: =AK368 -> 0 | N56: サッシ | O56: =BB368 -> 0 | P56: =BC368 -> 0 | T56: =IF(H56<>0,1-(S56/H56),0) -> 0 | U56: 塗装 | V56: =CR368 -> 0 | W56: =CS368 -> 0
B57: 総 合 計 | G57: =SUM(G54:G56) -> 0 | H57: =SUM(H54:H56) -> 0 | K57: 床 | L57: =AL368 -> 0 | M57: =AM368 -> 0 | U57: 建具 | V57: =CT368 -> 0 | W57: =CU368 -> 0
I58: ラグズ建築 | U58: 畳 | V58: =CV368 -> 0 | W58: =CW368 -> 0
E59: 内 訳 明 細 書 | J59: 2 | K59: 日付 | S59: / | U59: 申請 | V59: =CX368 -> 0 | W59: =CY368 -> 0
A61: 名 称 | E61: 数量 | F61: 呼称 | G61: 単 価 | H61: 金 額 | I61: 定価 | J61: 備 考 | K61: 職人 | L61: 人工 | M61: 人当 | N61: 費用① | O61: 材料 | P61: 数量 | Q61: 単価 | R61: 費用② | S61: 原価 | T61: 粗利率 | U61: 枠より右は絶対触らない。 | V61: =K49 -> 解体 | X61: =K50 -> 設備 | Z61: =K51 -> 電気 | AB61: =K52 -> ガス | AD61: =K53 -> 大工 | AF61: =K54 -> クロス | AH61: =K55 -> 左官 | AJ61: =K56 -> 清掃 | AL61: =K57 -> 床 | AN61: =N49 -> 仮設 | AP61: =N50 -> 養生 | AR61: =N51 -> 足場 | AT61: =N52 -> 板金 | AV61: =N53 -> 屋根 | AX61: =N54 -> 塗装 | AZ61: =N55 -> 建具 | BB61: =N56 -> サッシ | BD61: =U36 -> 養生 | BF61: =U37 -> 産廃 | BH61: =U38 -> 材木 | BJ61: =U39 -> 建材 | BL61: =U40 -> 電材 | BN61: =U41 -> 住設 | BP61: =U42 -> サッシ | BR61: =U43 -> 足場 | BT61: =U44 -> 外壁 | BV61: =U45 -> 外構 | BX61: =U46 -> 雑費 | BZ61: =U47 -> ガス | CB61: =U48 -> ラグズ | CD61: =U49 -> 解体 | CF61: =U50 -> 大工 | CH61: =U51 -> 電気 | CJ61: =U52 -> 設備 | CL61: =U53 -> クロス | CN61: =U54 -> 左官 | CP61: =U55 -> 清掃 | CR61: =U56 -> 塗装 | CT61: =U57 -> 建具 | CV61: =U58 -> 畳 | CX61: =U59 -> 申請
...

Sheet 見積表紙
F2: 御 見 積 書
B6: =見積内訳書!L2 -> 浅野誠一郎 | D6: 様邸 | E6: 金額 | G6: =見積内訳書!H57 -> 0 | Q6: - | V6: ←データ 枠内入力禁止
H7: (消費税込)
B9: 工 事 名 | C9: リフォーム工事 | J9: 御支払条件 | N9: お支払イメージは下記参照
B11: 工 事 場 所 | C11: =見積内訳書!L4 -> 0 | N11: ※振込手数料はお施主様負担でお願いいたします
V12: 下記データ↓↓
B13: 工 期 | C13: お打ち合わせによる | N13: =見積内訳書!L13 -> 0 | V13: 触ってはダメ
V14: =見積内訳書!H57*0 -> 0
B15: 見積有効期間 | C15: =見積内訳書!L6 -> 0 | F15: より | G15: １か月 | J15: 担当者 | N15: =見積内訳書!L10 -> 0 | V15: =見積内訳書!H57*0.2 -> 0
V16: =見積内訳書!H57*0.5 -> 0
B17: 工 事 概 要 | C17: 内訳明細書に準ずる | V17: =見積内訳書!H57*0.3 -> 0
B19: （備 考） | C19: 工事中に電気・水道を使用させて頂きます。
A22: 上記のとおり御見積り申しあげます
B25: お支払イメージ
S29: 印

Sheet 原価台帳
A1: 工 事 台 帳
A3: 契約番号 | Q3: 担当者 | U3: =見積内訳書!L10 -> 0 | AH3: 売上推移表
A4: 工事名 | E4: =見積内訳書!L2 -> 浅野誠一郎 | Q4: =見積内訳書!B33 -> 0 | AH4: 受注金額（抜き） | AK4: =見積内訳書!H54 -> 0 | AO4: 予算原価 | AT4: =O72 -> 0 | AX4: 完工原価 | BC4: =V72 -> 0 | BG4: 請求金額 | BL4: =AG72 -> 0
AH5: 追加金額①
A6: 工期 | E6: 45785 | M6: ～ | Q6: 45935 | AH6: 追加金額②
G7: 完工原価予想（税抜き合計-完工原価） | AH7: 追加金額③ | BS7: ↑この色のみ入力
G8: =AK8-BC4 -> 0 | AH8: 合計金額 | AK8: =SUM(AK4:AN7) -> 0 | AO8: 予算粗利率 | AT8: =1-(AT4/AK8) -> #DIV/0! | AX8: 完工粗利率 | BC8: =1-(BC4/AK8) -> #DIV/0! | BG8: 請求後粗利率 | BL8: =1-(BL4/AK8) -> #DIV/0!
AH10: 請求・入金情報（税込）
AH11: 項目 | AV11: 請求日 | AZ11: 請求金額 | BD11: 入金日 | BH11: 入金金額 | BL11: 手数料
AH13: 契約金 | BS13: ↑白は、自動入力
A14: 顧客名 | E14: =見積内訳書!L2 -> 浅野誠一郎 | X14: 様 | AH14: 着工金
AH15: 中間金
A16: 住所 | E16: =見積内訳書!L4 -> 0 | AH16: 完工金 | BS16: ※ 金額はすべて、税抜き珪酸
AH17: 【合計】
A20: 原価情報（明細）
A21: NO | C21: 職種 | D21: 業者名 | O21: 実行予算（税抜） | V21: 完工実績（抜き） | AC21: 請求1 | AD21: 請求2 | AE21: 請求3 | AF21: 請求4 | AG21: 請求実績（抜き） | AK21: 予算差額 | AM21: 請求日 | AQ21: 支払日 | AU21: 詳細
A22: 1 | C22: =見積内訳書!K49 -> 解体 | O22: =見積内訳書!M49 -> 0 | AG22: =AC22+AD22+AE22+AF22 -> 0 | AK22: =O22-AG22 -> 0
A23: 2 | C23: =見積内訳書!K50 -> 設備 | O23: =見積内訳書!M50 -> 0 | AG23: =AC23+AD23+AE23+AF23 -> 0 | AK23: =O23-AG23 -> 0
A24: 3 | C24: =見積内訳書!K51 -> 電気 | O24: =見積内訳書!M51 -> 0 | AG24: =AC24+AD24+AE24+AF24 -> 0 | AK24: =O24-AG24 -> 0
A25: 4 | C25: =見積内訳書!K52 -> ガス | O25: =見積内訳書!M52 -> 0 | AG25: =AC25+AD25+AE25+AF25 -> 0 | AK25: =O25-AG25 -> 0
A26: 5 | C26: =見積内訳書!K53 -> 大工 | O26: =見積内訳書!M53 -> 0 | AG26: =AC26+AD26+AE26+AF26 -> 0 | AK26: =O26-AG26 -> 0
A27: 6 | C27: =見積内訳書!K54 -> クロス | O27: =見積内訳書!M54 -> 0 | AG27: =AC27+AD27+AE27+AF27 -> 0 | AK27: =O27-AG27 -> 0
A28: 7 | C28: =見積内訳書!K55 -> 左官 | O28: =見積内訳書!M55 -> 0 | AG28: =AC28+AD28+AE28+AF28 -> 0 | AK28: =O28-AG28 -> 0
A29: 8 | C29: =見積内訳書!K56 -> 清掃 | O29: =見積内訳書!M56 -> 0 | AG29: =AC29+AD29+AE29+AF29 -> 0 | AK29: =O29-AG29 -> 0
A30: 9 | C30: =見積内訳書!K57 -> 床 | O30: =見積内訳書!M57 -> 0 | AG30: =AC30+AD30+AE30+AF30 -> 0 | AK30: =O30-AG30 -> 0
A31: 10 | C31: =見積内訳書!N49 -> 仮設 | O31: =見積内訳書!P49 -> 0 | AG31: =AC31+AD31+AE31+AF31 -> 0 | AK31: =O31-AG31 -> 0
A32: 11 | C32: =見積内訳書!N50 -> 養生 | O32: =見積内訳書!P50 -> 0 | AG32: =AC32+AD32+AE32+AF32 -> 0 | AK32: =O32-AG32 -> 0
A33: 12 | C33: =見積内訳書!N51 -> 足場 | O33: =見積内訳書!P51 -> 0 | AG33: =AC33+AD33+AE33+AF33 -> 0 | AK33: =O33-AG33 -> 0
A34: 13 | C34: =見積内訳書!N52 -> 板金 | O34: =見積内訳書!P52 -> 0 | AG34: =AC34+AD34+AE34+AF34 -> 0 | AK34: =O34-AG34 -> 0
A35: 14 | C35: =見積内訳書!N53 -> 屋根 | O35: =見積内訳書!P53 -> 0 | AG35: =AC35+AD35+AE35+AF35 -> 0 | AK35: =O35-AG35 -> 0
A36: 15 | C36: =見積内訳書!N54 -> 塗装 | O36: =見積内訳書!P54 -> 0 | AG36: =AC36+AD36+AE36+AF36 -> 0 | AK36: =O36-AG36 -> 0
A37: 16 | C37: =見積内訳書!N55 -> 建具 | O37: =見積内訳書!P55 -> 0 | AG37: =AC37+AD37+AE37+AF37 -> 0 | AK37: =O37-AG37 -> 0
A38: 17 | C38: =見積内訳書!N56 -> サッシ | O38: =見積内訳書!P56 -> 0 | AG38: =AC38+AD38+AE38+AF38 -> 0 | AK38: =O38-AG38 -> 0 | BQ38: =IF(V38="","",V38)
A39: 18 | C39: =見積内訳書!U36 -> 養生 | O39: =見積内訳書!W36 -> 0 | AG39: =AC39+AD39+AE39+AF39 -> 0 | AK39: =O39-AG39 -> 0 | BQ39: =IF(V39="","",V39)
A40: 19 | C40: =見積内訳書!U37 -> 産廃 | O40: =見積内訳書!W37 -> 0 | AG40: =AC40+AD40+AE40+AF40 -> 0 | AK40: =O40-AG40 -> 0 | BQ40: =IF(V40="","",V40)
A41: 20 | C41: =見積内訳書!U38 -> 材木 | O41: =見積内訳書!W38 -> 0 | AG41: =AC41+AD41+AE41+AF41 -> 0 | AK41: =O41-AG41 -> 0 | BQ41: =IF(V41="","",V41)
A42: 21 | C42: =見積内訳書!U39 -> 建材 | O42: =見積内訳書!W39 -> 0 | AG42: =AC42+AD42+AE42+AF42 -> 0 | AK42: =O42-AG42 -> 0 | BQ42: =IF(V42="","",V42)
A43: 22 | C43: =見積内訳書!U40 -> 電材 | O43: =見積内訳書!W40 -> 0 | AG43: =AC43+AD43+AE43+AF43 -> 0 | AK43: =O43-AG43 -> 0 | BQ43: =IF(V43="","",V43)
A44: 23 | C44: =見積内訳書!U41 -> 住設 | O44: =見積内訳書!W41 -> 0 | AG44: =AC44+AD44+AE44+AF44 -> 0 | AK44: =O44-AG44 -> 0 | BQ44: =IF(V44="","",V44)
A45: 24 | C45: =見積内訳書!U42 -> サッシ | O45: =見積内訳書!W42 -> 0 | AG45: =AC45+AD45+AE45+AF45 -> 0 | AK45: =O45-AG45 -> 0 | BQ45: =IF(V45="","",V45)
...

Sheet 挨拶廻り
K2: 令和8年4月吉日
C3: ご近隣の皆様へ
F5: 工事着工のご挨拶
D7: 拝啓、時下益々ご清栄の事と、お慶び申し上げます。
D8: 平素は格別のご高配を賜り厚く御礼申し上げます。
D9: このたび下記のご住所にて、リフォーム工事を
D10: 着手させて頂く事となりました。
D11: 工事中は何かと、ご迷惑をおかけする事もあるかと存じますが
D12: 細心の注意を払いながら工事を進めて参りますので
D13: 何卒ご理解、ご協力賜わりますよう、お願い申し上げます。
D15: 工事名称 | E15: ： | F15: 谷口様水回りリフォーム工事
D16: 工事場所 | E16: ： | F16: 各務原市蘇原中央町2丁目40
D17: 工事期間 | E17: ： | F17: 令和8年5月11日～5月31日 (予定）
D18: 作業時間 | E18: ： | F18: 午前８時～午後１８時頃
D19: (騒音を伴わない作業は上記以外に行う事があります。）
D20: お家の 【困った...】 を解決します！
D21: リフォームや修理等で、お力になれる事がありましたら
D22: 下記まで 【お気軽にご相談ください】 ご相談お見積り無料
I26: 岐阜市今嶺4丁目5-20
I27: 代表取締役 栗本 佳一
I28: ＴＥＬ 058-374-5318
M29: HPはコチラから!!

Sheet ご請求書
D2: 請求書 | F2: No.1
B4: =見積内訳書!L2 -> 浅野誠一郎 | C4: 様 | F4: =TODAY() -> 46216
B7: お支払いは下記口座までお願いします
B8: 十六銀行/鏡島支店
B9: 【普通】 1326345
B10: 株式会社 ラグズ建築
B11: カ） ラグズケンチク | F11: 〒500-8388
B12: ※振込手数料はお客様負担にてお願いいたします。 | F12: 岐阜県岐阜市今嶺４丁目5-20
B13: お振込み金額（消費税込） | E13: =E42 -> 331095.6 | F13: TEL 058-374-5318
F14: E-mail info@rugs_reform.jp
B15: 登録番号 T2200001044783 | F15: 岐阜県知事許可 （般－8） 第103774号
B17: 工事名 | C17: 数量 | D17: 単位 | E17: 金 額 | F17: 備 考
A20: 1 | B20: 屋根改修工事 | E20: 300996
A21: 2
A22: 3
A23: 4
A24: 5
A25: 6
A26: 7
A27: 8
A28: 9
D39: 小 計 | E39: =SUM(E18:E38) -> 300996
D40: 消費税 | E40: =E39*0.1 -> 30099.6
D42: 合 計 | E42: =E39+E40+E41 -> 331095.6
A43: 備考

Sheet 仕様書大
B2: =見積内訳書!L2 -> 浅野誠一郎 | E2: 様邸 仕様書 | K2: 工 事 仕 様 書
B6: 部屋名 | C6: 部位 | D6: 仕様 | E6: メーカー・商品 | H6: 品番・色 | J6: 部屋名 | K6: 部位 | L6: 仕様 | M6: メーカー・商品 | P6: 品番・色 | R6: 部屋名 | S6: 部位 | T6: 仕様 | U6: メーカー・商品 | X6: 品番・色
B7: 玄関・ホール | C7: 天井 | D7: 壁紙 | E7: サンゲツ：SP級 | J7: トイレ | K7: 天井 | L7: 壁紙 | M7: サンゲツ：ＡＡ級 | R7: 洋室② | S7: 天井 | T7: 壁紙 | U7: サンゲツ：ＡＡ級
C9: 壁 | D9: 壁紙 | K9: 壁 | L9: 壁紙 | S9: 壁 | T9: 壁紙
C11: 床 | D11: フローリング | K11: 床 | L11: フローリング | S11: 床 | T11: フローリング
C13: 廻り縁 | D13: 無し | K13: 廻り縁 | L13: 無し | S13: 廻り縁 | T13: 無し
C15: 巾木 | D15: MDF（シート） | K15: 巾木 | L15: MDF（シート） | S15: 巾木 | T15: MDF（シート）
C17: 建具 | D17: 木製・既成 | K17: 建具 | L17: 木製・既成 | S17: 建具 | T17: 木製・既成
C19: 照明器具 | D19: シーリング | K19: 照明器具 | L19: シーリング | S19: 照明器具 | T19: シーリング
C21: 住宅設備 | D21: 無し | K21: 住宅設備 | L21: トイレ | S21: 住宅設備 | T21: 無し
C23: 他 | K23: 他 | S23: 他
B27: LDK | C27: 天井 | D27: 壁紙 | E27: サンゲツ：ＡＡ級 | J27: 廊下 | K27: 天井 | L27: 壁紙 | M27: サンゲツ：ＡＡ級 | R27: 洋室③ | S27: 天井 | T27: 壁紙 | U27: サンゲツ：ＡＡ級
C29: 壁 | D29: 壁紙 | K29: 壁 | L29: 壁紙 | S29: 壁 | T29: 壁紙
C31: 床 | D31: フローリング | K31: 床 | L31: フローリング | S31: 床 | T31: フローリング
C33: 廻り縁 | D33: 無し | K33: 廻り縁 | L33: 無し | S33: 廻り縁 | T33: 無し
C35: 巾木 | D35: MDF（シート） | K35: 巾木 | L35: MDF（シート） | S35: 巾木 | T35: MDF（シート）
C37: 建具 | D37: 木製・既成 | K37: 建具 | L37: 木製・既成 | S37: 建具 | T37: 木製・既成
C39: 照明器具 | D39: シーリング | K39: 照明器具 | L39: シーリング | S39: 照明器具 | T39: シーリング
C41: 住宅設備 | D41: キッチン | K41: 住宅設備 | L41: 無し | S41: 住宅設備 | T41: 無し
C43: 住宅設備 | D43: カップボード | K43: 他 | S43: 他
C45: 他
B47: 洗面室 | C47: 天井 | D47: 壁紙 | E47: サンゲツ：ＡＡ級 | J47: 洋室① | K47: 天井 | L47: 壁紙 | M47: サンゲツ：ＡＡ級 | R47: 洋室④ | S47: 天井 | T47: 壁紙 | U47: サンゲツ：ＡＡ級
C49: 壁 | D49: 壁紙 | K49: 壁 | L49: 壁紙 | S49: 壁 | T49: 壁紙
C51: 床 | D51: フローリング | K51: 床 | L51: フローリング | S51: 床 | T51: フローリング
C53: 廻り縁 | D53: 無し | K53: 廻り縁 | L53: 無し | S53: 廻り縁 | T53: 無し
C55: 巾木 | D55: MDF（シート） | K55: 巾木 | L55: MDF（シート） | S55: 巾木 | T55: MDF（シート）
C57: 建具 | D57: 木製・既成 | K57: 建具 | L57: 木製・既成 | S57: 建具 | T57: 木製・既成
C59: 照明器具 | D59: シーリング | K59: 照明器具 | L59: シーリング | S59: 照明器具 | T59: シーリング
C61: 住宅設備 | D61: 洗面化粧台 | K61: 住宅設備 | L61: 無し | S61: 住宅設備 | T61: 無し
C63: 他 | K63: 他 | S63: 他

Sheet 仕様書　中
B2: =見積内訳書!L2 -> 浅野誠一郎 | E2: 様邸 仕様書 | H2: 工 事 仕 様 書
B6: 部屋名 | C6: 部位 | D6: 仕様 | E6: メーカー・商品 | H6: 品番・色 | J6: 部屋名 | K6: 部位 | L6: 仕様 | M6: メーカー・商品 | P6: 品番・色
B7: 玄関・ホール | C7: 天井 | D7: 壁紙 | E7: サンゲツ：SP級 | J7: トイレ | K7: 天井 | L7: 壁紙 | M7: サンゲツ：ＡＡ級
C9: 壁 | D9: 壁紙 | K9: 壁 | L9: 壁紙
C11: 床 | D11: フローリング | K11: 床 | L11: フローリング
C13: 廻り縁 | D13: 無し | K13: 廻り縁 | L13: 無し
C15: 巾木 | D15: MDF（シート） | K15: 巾木 | L15: MDF（シート）
C17: 建具 | D17: 木製・既成 | K17: 建具 | L17: 木製・既成
C19: 照明器具 | D19: シーリング | K19: 照明器具 | L19: シーリング
C21: 住宅設備 | D21: 無し | K21: 住宅設備 | L21: トイレ
C23: 他 | K23: 他
B27: LDK | C27: 天井 | D27: 壁紙 | E27: サンゲツ：ＡＡ級 | J27: 廊下 | K27: 天井 | L27: 壁紙 | M27: サンゲツ：ＡＡ級
C29: 壁 | D29: 壁紙 | K29: 壁 | L29: 壁紙
C31: 床 | D31: フローリング | K31: 床 | L31: フローリング
C33: 廻り縁 | D33: 無し | K33: 廻り縁 | L33: 無し
C35: 巾木 | D35: MDF（シート） | K35: 巾木 | L35: MDF（シート）
C37: 建具 | D37: 木製・既成 | K37: 建具 | L37: 木製・既成
C39: 照明器具 | D39: シーリング | K39: 照明器具 | L39: シーリング
C41: 住宅設備 | D41: キッチン | K41: 住宅設備 | L41: 無し
C43: 住宅設備 | D43: カップボード | K43: 他
C45: 他
B47: 洗面室 | C47: 天井 | D47: 壁紙 | E47: サンゲツ：ＡＡ級 | J47: 洋室① | K47: 天井 | L47: 壁紙 | M47: サンゲツ：ＡＡ級
C49: 壁 | D49: 壁紙 | K49: 壁 | L49: 壁紙
C51: 床 | D51: フローリング | K51: 床 | L51: フローリング
C53: 廻り縁 | D53: 無し | K53: 廻り縁 | L53: 無し
C55: 巾木 | D55: MDF（シート） | K55: 巾木 | L55: MDF（シート）
C57: 建具 | D57: 木製・既成 | K57: 建具 | L57: 木製・既成
C59: 照明器具 | D59: シーリング | K59: 照明器具 | L59: シーリング
C61: 住宅設備 | D61: 洗面化粧台 | K61: 住宅設備 | L61: 無し
C63: 他 | K63: 他
B67: 洗面室 | C67: 天井 | D67: 壁紙 | E67: サンゲツ：ＡＡ級 | J67: 洋室① | K67: 天井 | L67: 壁紙 | M67: サンゲツ：ＡＡ級
C69: 壁 | D69: 壁紙 | K69: 壁 | L69: 壁紙
C71: 床 | D71: フローリング | K71: 床 | L71: フローリング
C73: 廻り縁 | D73: 無し | K73: 廻り縁 | L73: 無し
C75: 巾木 | D75: MDF（シート） | K75: 巾木 | L75: MDF（シート）
C77: 建具 | D77: 木製・既成 | K77: 建具 | L77: 木製・既成
C79: 照明器具 | D79: シーリング | K79: 照明器具 | L79: シーリング
C81: 住宅設備 | D81: 洗面化粧台 | K81: 住宅設備 | L81: 無し
C83: 他 | K83: 他

Sheet 工程表７日
B2: 工 程 表
B6: 工事名 | C6: =見積内訳書!A33 -> 0 | E6: 様邸改装工事 | M6: 担当 ： | O6: =見積内訳書!L10 -> 0
C10: 月 | E10: 火 | G10: 水 | I10: 木 | K10: 金 | M10: 土 | O10: 日 | Q10: 月
C11: AM | D11: PM | E11: AM | F11: PM | G11: AM | H11: PM | I11: AM | J11: PM | K11: AM | L11: PM | M11: AM | N11: PM | O11: AM | P11: PM | Q11: AM | R11: PM
B12: 仮設工事
C15: 養生
B16: 解体工事
C19: キッチン解体・撤去
B20: 配管設備工事
D23: 配管移設
B24: 電気工事
E27: 電気配線移設
B28: ガス工事
F31: ガス管移設
B32: 大工工事
G35: キッチン下地
B36: 住宅設備工事
I39: キッチン組立
B52: 備考 | C52: ※作業時間はAM8：30～PM17：30頃を予定しております
C53: ※雨天時等で、多少工程が前後する可能性がございます

Sheet 工程表半月
B2: 工 程 表
C5: =見積内訳書!A33 -> 0 | G5: 様邸改装工事
B6: 工事名 | W6: 担当 ： | Y6: =見積内訳書!L10 -> 0
C10: 月 | E10: 火 | G10: 水 | I10: 木 | K10: 金 | M10: 土 | O10: 日 | Q10: 月 | S10: 火 | U10: 水 | W10: 木 | Y10: 金 | AA10: 土 | AC10: 日
C11: AM | D11: PM | E11: AM | F11: PM | G11: AM | H11: PM | I11: AM | J11: PM | K11: AM | L11: PM | M11: AM | N11: PM | O11: AM | P11: PM | Q11: AM | R11: PM | S11: AM | T11: PM | U11: AM | V11: PM | W11: AM | X11: PM | Y11: AM | Z11: PM | AA11: AM | AB11: PM | AC11: AM | AD11: PM
B12: 仮設工事
B16: 解体工事
B20: 大工工事
B24: 電気工事
B28: クロス工事
B32: 屋根工事
B52: 備考 | C52: ※作業時間はAM8：30～PM17：30頃を予定しております
C53: ※雨天時等で、多少工程が前後する可能性がございます

Sheet 工程表１ヶ月
B2: 工 程 表
B6: 工事名 | C6: =見積内訳書!A33 -> 0 | H6: 様邸改装工事
C9: 45866 | E9: 45867 | G9: 45868 | I9: 45869 | K9: 45870 | M9: 45871 | O9: 45872 | Q9: 45873 | S9: 45874 | U9: 45875 | W9: 45876 | Y9: 45877 | AA9: 45878 | AC9: 45879 | AE9: 45880 | AG9: 45881 | AI9: 45882 | AK9: 45883 | AM9: 45884 | AO9: 45885 | AQ9: 45886 | AS9: 45887 | AU9: 45888 | AW9: 45889 | AY9: 45890 | BA9: 45891 | BC9: 45892 | BE9: 45893 | BG9: 45894 | BI9: 45895 | BK9: 45896
C10: 月 | E10: 火 | G10: 水 | I10: 木 | K10: 金 | M10: 土 | O10: 日 | Q10: 月 | S10: 火 | U10: 水 | W10: 木 | Y10: 金 | AA10: 土 | AC10: 日 | AE10: 月 | AG10: 火 | AI10: 水 | AK10: 木 | AM10: 金 | AO10: 土 | AQ10: 日 | AS10: 月 | AU10: 火 | AW10: 水 | AY10: 木 | BA10: 金 | BC10: 土 | BE10: 日 | BG10: 月 | BI10: 火 | BK10: 水
C11: AM | D11: PM | E11: AM | F11: PM | G11: AM | H11: PM | I11: AM | J11: PM | K11: AM | L11: PM | M11: AM | N11: PM | O11: AM | P11: PM | Q11: AM | R11: PM | S11: AM | T11: PM | U11: AM | V11: PM | W11: AM | X11: PM | Y11: AM | Z11: PM | AA11: AM | AB11: PM | AC11: AM | AD11: PM | AE11: AM | AF11: PM | AG11: AM | AH11: PM | AI11: AM | AJ11: PM | AK11: AM | AL11: PM | AM11: AM | AN11: PM | AO11: AM | AP11: PM | AQ11: AM | AR11: PM | AS11: AM | AT11: PM | AU11: AM | AV11: PM | AW11: AM | AX11: PM | AY11: AM | AZ11: PM | BA11: AM | BB11: PM | BC11: AM | BD11: PM | BE11: AM | BF11: PM | BG11: AM | BH11: PM | BI11: AM | BJ11: PM | BK11: AM | BL11: PM
B12: 仮設工事
C15: 仮設トイレ | BK15: クリーニング
B16: 解体工事
C19: 内装解体・サッシ解体
B20: 配管設備工事
AE23: 配管移設
B24: 電気工事
AK27: 配線移設 | BI27: 仕上げ
B28: 大工工事
Q31: サッシ取付 | U31: 床組 | AG31: 壁断熱 | AM31: 造作・天井組 | AV31: ２階 フィルム
B32: 床工事
BA35: フローリング・巾木
B36: 内装工事
BG39: クロス貼り
B40: 左官工事
Y43: 内部土間補修
B72: 備考 | C72: ※本工程は、仮の工程表になります
C73: ※作業時間はAM8：30～PM17：30頃を予定しております
C74: ※雨天時等で、多少工程が前後する可能性がございます

Sheet 工程表2ヶ月
B2: 工 程 表
B6: 工事名 | C6: =見積内訳書!A33 -> 0 | H6: 様邸改装工事
C9: 45897 | E9: 45898 | G9: 45899 | I9: 45900 | K9: 45901 | M9: 45902 | O9: 45903 | Q9: 45904 | S9: 45905 | U9: 45906 | W9: 45907 | Y9: 45908 | AA9: 45909 | AC9: 45910 | AE9: 45911 | AG9: 45912 | AI9: 45913 | AK9: 45914 | AM9: 45915 | AO9: 45916 | AQ9: 45917 | AS9: 45918 | AU9: 45919 | AW9: 45920 | AY9: 45921 | BA9: 45922 | BC9: 45923 | BE9: 45924 | BG9: 45925 | BI9: 45926 | BK9: 45927
C10: 木 | E10: 金 | G10: 土 | I10: 日 | K10: 月 | M10: 火 | O10: 水 | Q10: 木 | S10: 金 | U10: 土 | W10: 日 | Y10: 月 | AA10: 火 | AC10: 水 | AE10: 木 | AG10: 金 | AI10: 土 | AK10: 日 | AM10: 月 | AO10: 火 | AQ10: 水 | AS10: 木 | AU10: 金 | AW10: 土 | AY10: 日 | BA10: 月 | BC10: 火 | BE10: 水 | BG10: 木 | BI10: 金 | BK10: 土
C11: AM | D11: PM | E11: AM | F11: PM | G11: AM | H11: PM | I11: AM | J11: PM | K11: AM | L11: PM | M11: AM | N11: PM | O11: AM | P11: PM | Q11: AM | R11: PM | S11: AM | T11: PM | U11: AM | V11: PM | W11: AM | X11: PM | Y11: AM | Z11: PM | AA11: AM | AB11: PM | AC11: AM | AD11: PM | AE11: AM | AF11: PM | AG11: AM | AH11: PM | AI11: AM | AJ11: PM | AK11: AM | AL11: PM | AM11: AM | AN11: PM | AO11: AM | AP11: PM | AQ11: AM | AR11: PM | AS11: AM | AT11: PM | AU11: AM | AV11: PM | AW11: AM | AX11: PM | AY11: AM | AZ11: PM | BA11: AM | BB11: PM | BC11: AM | BD11: PM | BE11: AM | BF11: PM | BG11: AM | BH11: PM | BI11: AM | BJ11: PM | BK11: AM | BL11: PM
B12: 仮設工事
C15: 足場 | BA15: 足場解体 | BE15: クリーニング
B16: 板金工事
E19: 外部板金
B20: 塗装工事
AM23: 外部塗装
B24: 左官工事
Y27: 土間うち
B28: 床工事
C31: フリーフロア
B32: 大工工事
K35: 水廻り・作業部屋造作
B36: 内装工事
AQ39: クロス
B40: 住宅設備工事
BA43: トイレ・洗面・キッチン
B44: 電気工事
BA47: 仕上げ
B72: 備考 | C72: ※本工程は、仮の工程表になります
C73: ※作業時間はAM8：30～PM17：30頃を予定しております
C74: ※雨天時等で、多少工程が前後する可能性がございます

Sheet 外部仕様書
A1: ●外部
A2: 屋根・軒 | B2: 屋根 | C2: 破風・鼻隠し | D2: 軒天 | E2: 通気見切 | G2: 開口部 | H2: サッシ（外部） | I2: サッシ（内部） | J2: ガラス | K2: 網戸 | L2: ハンドル
B3: イメージ | C3: 取替 | D3: 既設 | N3: ←イメージ図/取替/既設
B4: 陶器瓦 | C4: 窯業系化粧破風 | D4: 塗装済珪酸カルシウム板 | E4: BM-2 | H4: アルミ樹脂複合 | I4: アルミ樹脂複合 | J4: LOW-Eガラス | K4: 固定網戸 | L4: オペレーターハンドル | N4: ← 材質
B5: 新東 セラムFフラット | C5: 神島化学 | D5: 神島化学 | E5: 神島化学 | H5: YKKAP | I5: YKKAP | J5: アルゴンガス | K5: スライド網戸 | N5: ← メーカー
B6: ブラック | C6: Wミルトアイボリー | D6: ラフォーレティンバー | E6: ブラウン | H6: エピソードNEO-R | I6: エピソードNEO-R | J6: 遮熱ブルー | K6: ブラックネット | N6: ←シリーズ/色
H7: プラチナステン | I7: ホワイト | J7: 透明/型 | N7: ←シリーズ/色
N8: ←サイズ/他
N9: ←サイズ/他
B10: 軒樋 | C10: 這樋（はいどい） | D10: 竪樋 | H10: 雨戸 | I10: 面格子 | J10: 勝手口ドア | K10: 玄関庇
B12: ファインNF-1型 | C12: 丸 S30 | D12: 丸 S30
B13: Panasonic | C13: Panasonic | D13: Panasonic
B14: ホワイト | C14: ブラック | D14: ブラック
A18: 玄関ポーチ | B18: 軒天/水平軒天 | C18: ポーチタイル | D18: 玄関タイル（土間収納共通） | G18: フラットルーフ | H18: 建物一体型 | I18: 物干しセット
B20: 塗装済珪酸カルシウム板 | C20: 磁器タイル | D20: 磁器タイル
B21: 神島化学 | C21: LIXIL | D21: LIXIL
B22: ラフォーレティンバー | C22: コンテⅡ | D22: コンテⅡ
C23: Con5 | D23: Con5
C24: 目地： | D24: 目地：
D25: 300角
A26: 外部 | B26: 外壁（メイン） | C26: 外壁（アクセント） | E26: オーバーハング水切り | F26: 土台水切り | G26: 玄関ドア | H26: 単体断熱玄関ドア
B28: オリジナル | C28: オリジナル | E28: ガルバリウム製 | F28: ガルバリウム製
B29: 柄： | C29: 柄： | E29: トーコー | F29: トーコー
B30: 色： | C30: 色： | E30: ホワイト | F30: ホワイト
B31: 目地： | C31: 目地：
A33: 基礎 | B33: 既設 | C33: 基礎見掛かり：モルタル刷毛引き仕上げ | G33: 他 | H33: エクステリア
B34: 工事無し | C34: 床下換気：城東テクノ/基礎パッキン | E34: 床束：鋼製束
C35: 床束：鋼製束
D37: =見積内訳書!L19 -> 〒500-8388 | H37: =見積内訳書!L2 -> 浅野誠一郎 | I37: 様邸改装工事 | K37: 担当 | L37: 作成日
D38: =見積内訳書!L20 -> 岐阜県岐阜市今嶺４丁目５−２０ | H38: 外部仕上げ表 | K38: =見積内訳書!L10 -> 0 | L38: =TODAY() -> 46216

Sheet １階仕上げ表
A1: ●内部 1階
A2: 玄関 | B2: 床 | C2: 廻縁なし | D2: 巾木 | E2: 窓枠 | F2: 壁 | G2: 天井 | H2: 玄関框 | I2: 収納 | J2: 床 | K2: 廻縁なし | L2: 巾木 | M2: 窓枠 | N2: 壁 | O2: 天井 | P2: アクセント
B3: イメージ | C3: 取替 | F3: 既設 | R3: ←イメージ図/取替/既設
R4: ←メーカー
R5: ←シリーズ
R6: ←品番/色
A7: 土間収納 | B7: 床 | C7: 廻縁なし | D7: 巾木 | E7: 窓枠 | F7: 壁 | G7: 天井 | H7: アクセント | I7: 洗面脱衣室 | J7: 床 | K7: 廻縁なし | L7: 巾木 | M7: 窓枠 | N7: 壁 | O7: 天井 | P7: アクセント
A12: LDK | B12: 床 | C12: 廻縁なし | D12: 巾木 | E12: 窓枠 | F12: 壁 | G12: 天井 | H12: アクセント | I12: トイレ | J12: 床 | K12: 廻縁なし | L12: 巾木 | M12: 窓枠 | N12: 壁 | O12: 天井 | P12: アクセント
B17: キッチン前笠木 | H17: タイル | I17: 和室 | J17: 畳 | K17: 畳寄せ | L17: 巾木 | M17: 窓枠 | N17: 壁 | O17: 天井 | P17: 床
A23: キッチン | B23: 床 | C23: 廻縁なし | D23: 巾木 | E23: 窓枠 | F23: 壁 | G23: 天井 | H23: エコカラット | I23: 廊下 | J23: 床 | K23: 廻縁なし | L23: 巾木 | M23: 窓枠 | N23: 壁 | O23: 天井 | P23: アクセント
A28: ホール | B28: 床 | C28: 廻縁なし | D28: 巾木 | E28: 窓枠 | F28: 壁 | G28: 天井 | H28: アクセント | I28: 洋室 | J28: 床 | K28: 廻縁なし | L28: 巾木 | M28: 窓枠 | N28: 壁 | O28: 天井 | P28: アクセント
A33: 他 | B33: 床 | C33: 廻縁なし | D33: 巾木 | E33: 窓枠 | F33: 壁 | G33: 天井 | H33: アクセント | J33: MEMO
D37: =見積内訳書!L19 -> 〒500-8388 | J37: =見積内訳書!L2 -> 浅野誠一郎 | L37: 様邸 改装工事 | O37: 担当 | P37: 作成日
D38: =見積内訳書!L20 -> 岐阜県岐阜市今嶺４丁目５−２０ | J38: １階内部仕上げ表 | O38: =見積内訳書!L10 -> 0 | P38: =TODAY() -> 46216

Sheet ２階仕上げ表
A1: ●内部 2階
A2: 階段 | B2: 踏板 | C2: 段鼻 | D2: 蹴上 | E2: ささら | F2: 壁 | G2: 天井 | H2: アクセント | I2: 子供部屋 | J2: 床 | K2: 廻縁なし | L2: 巾木 | M2: 窓枠 | N2: 壁 | O2: 天井 | P2: アクセント
B3: イメージ | C3: 取替 | F3: 既設 | R3: ←イメージ図/取替/既設
R4: ←メーカー
R5: ←シリーズ
R6: ←品番/色
B7: 上段框 | C7: 廻縁なし | D7: 巾木 | E7: 窓枠 | F7: 手摺 | G7: 笠木 | H7: 見切り | I7: 納戸 | J7: 床 | K7: 廻縁なし | L7: 巾木 | M7: 窓枠 | N7: 壁 | O7: 天井 | P7: アクセント
A12: ホール | B12: 床 | C12: 廻縁なし | D12: 巾木 | E12: 窓枠 | F12: 壁 | G12: 天井 | H12: アクセント | I12: トイレ | J12: 床 | K12: 廻縁なし | L12: 巾木 | M12: 窓枠 | N12: 壁 | O12: 天井 | P12: アクセント
A17: 主寝室 | B17: キッチン前笠木 | H17: タイル | I17: 洋室① | J17: 畳 | K17: 畳寄せ | L17: 巾木 | M17: 窓枠 | N17: 壁 | O17: 天井 | P17: 床
A23: WIC | B23: 床 | C23: 廻縁なし | D23: 巾木 | E23: 窓枠 | F23: 壁 | G23: 天井 | H23: エコカラット | I23: 洋室② | J23: 床 | K23: 廻縁なし | L23: 巾木 | M23: 窓枠 | N23: 壁 | O23: 天井 | P23: アクセント
A28: 書斎 | B28: 床 | C28: 廻縁なし | D28: 巾木 | E28: 窓枠 | F28: 壁 | G28: 天井 | H28: アクセント | I28: 洋室③ | J28: 床 | K28: 廻縁なし | L28: 巾木 | M28: 窓枠 | N28: 壁 | O28: 天井 | P28: アクセント
A33: 他 | B33: 床 | C33: 廻縁なし | D33: 巾木 | E33: 窓枠 | F33: 壁 | G33: 天井 | H33: アクセント | J33: MEMO
D37: =見積内訳書!L19 -> 〒500-8388 | J37: =見積内訳書!L2 -> 浅野誠一郎 | L37: 様邸 改装工事 | O37: 担当 | P37: 作成日
D38: =見積内訳書!L20 -> 岐阜県岐阜市今嶺４丁目５−２０ | J38: 2階内部仕上げ表 | O38: =見積内訳書!L10 -> 0 | P38: =TODAY() -> 46216

Sheet 建具表
A1: ●建具表 | I1: ●内部収納・玄関収納
A2: １階 | B2: 【1】LDK | C2: 【2】ホール | D2: 【3】居間 | E2: 【4】洋室 | F2: 【5】収納 | G2: 【6】ホール収納 | H2: 【7】脱衣室 | I2: 枕棚・吊りパイプ | O2: ←部屋名
B3: イメージ | C3: 取替 | D3: 既設 | E3: 取替 | F3: 既設 | G3: 取替 | H3: 取替 | I3: 普及品
I4: ホワイト
I7: 中段棚 | O7: ←イメージ図/取替/既設
B8: 片引き戸 | I8: 普及品 | O8: ← 開き/片引き/引き違い
B9: Panasonic | I9: ホワイト | O9: ← メーカー
B10: LC型 | O10: ←シリーズ
B11: ウォールナット | I11: 和室 | O11: ←色
B12: 2035*1645 | O12: ←サイズ/他
B13: 固定枠 | O13: ←サイズ/他
B14: 【8】トイレ | C14: 【9】和室 | D14: 【10】洋室2 | I14: ●設備・その他
I16: 太陽光
I18: 給湯器 | J18: ガス給湯器
J19: エコキュート
I20: カラーTVドアホン
I22: 換気設備 | J22: 第３種 | M22: シルバー
I24: 屋外設備
A26: ２階 | B26: 【11】LDK | C26: 【12】ホール | D26: 【13】洋室 | E26: 【14】洋室 | F26: 【15】収納 | G26: 【16】ホール収納 | H26: 【17】脱衣室 | I26: 床暖房・ガスコック
I28: 天井点検口 | M28: 脱衣室
I29: 床下収納庫 | M29: 脱衣室
I30: 室内物干し
I32: トイレ収納 | M32: １階トイレ
M33: ２階トイレ
I34: システム収納
I36: 集成材カウンター
B38: 【18】トイレ | E38: 開き戸 標準仕様 | G38: 引き戸標準仕様
I41: 可動棚
E44: カバー蝶番 | F44: サテンシルバー（塗装） | G44: 角型引手 C1型 | H44: サテンシルバー（塗装）
E45: ハンドルA1型 | F45: サテンシルバー（塗装）
A49: 特記事項
A51: MEMO | C51: 枕棚 標準 FL+1800 | E51: キッチンカウンター FL+1050 | I51: ニッチ
C52: 中段 標準 FL+800 | E52: 階段笠木 FL+1100
D53: =見積内訳書!L19 -> 〒500-8388 | I53: =見積内訳書!L2 -> 浅野誠一郎 | J53: 様邸 改装工事 | L53: 担当 | M53: 作成日
D54: =見積内訳書!L20 -> 岐阜県岐阜市今嶺４丁目５−２０ | I54: 建具表 | L54: =見積内訳書!L10 -> 0 | M54: =TODAY() -> 46216

Sheet １階　照明器具・住宅設備
A1: ● １階 住宅設備/照明器具
A2: 玄関 | B2: 照明器具 | C2: スイッチ | D2: コンセント | E2: リモコン | I2: キッチン | J2: 照明器具 | K2: スイッチ | L2: コンセント | M2: 給湯リモコン | O2: 住宅設備 | P2: 住宅設備②
B3: イメージ | C3: 取替 | R3: ←イメージ図/取替/既設
C4: Panasonic | D4: Panasonic | J4: Panasonic | K4: Panasonic | L4: Panasonic | O4: クリナップ | R4: ←メーカー
C5: コスモ/ホタル | D5: コスモ | J5: ダウンライト/100 | K5: コスモ/ホタル | L5: コスモ | O5: ラクエラ | R5: ←シリーズ
C6: 2口 | D6: 2口 | J6: 昼白色 | K6: 2口 | L6: 2口 | O6: 別紙参照 | R6: ←品番/色
A7: 土間収納 | B7: 照明器具 | C7: スイッチ | D7: コンセント | E7: リモコン | I7: 洗面脱衣室 | J7: 照明器具 | K7: スイッチ | L7: コンセント | M7: リモコン | O7: 住宅設備 | P7: 住宅設備②
C9: Panasonic | D9: Panasonic | J9: Panasonic | K9: Panasonic | L9: Panasonic | O9: Panasonic
C10: コスモ/ホタル | D10: コスモ | J10: ダウンライト/100 | K10: コスモ/ホタル | L10: コスモ | O10: C-ライン
C11: 2口 | D11: 2口 | J11: 昼白色 | K11: 2口 | L11: 2口 | O11: 別紙参照
A12: ホール | B12: 照明器具 | C12: スイッチ | D12: コンセント | E12: リモコン | I12: 浴室 | J12: 住宅設備 | K12: スイッチ | L12: 給湯リモコン | M12: 浴暖リモコン
C14: Panasonic | D14: Panasonic | J14: TOTO | K14: Panasonic
C15: コスモ/ホタル | D15: コスモ | J15: サザナ | K15: コスモ/ホタル
C16: 2口 | D16: 2口 | J16: 別紙参照 | K16: 2口
A17: 廊下 | B17: 照明器具 | C17: スイッチ | D17: コンセント | E17: リモコン | I17: トイレ | J17: 照明器具 | K17: スイッチ | L17: コンセント | M17: リモコン | O17: 住宅設備 | P17: 住宅設備②
C20: Panasonic | D20: Panasonic | K20: Panasonic | L20: Panasonic | O20: TOTO
C21: コスモ/ホタル | D21: コスモ | K21: コスモ/ホタル | L21: コスモ | O21: ZJ
C22: 2口 | D22: 2口 | K22: 2口 | L22: 2口 | O22: 別紙参照
A23: 居間 | B23: 照明器具 | C23: スイッチ | D23: コンセント | E23: リモコン | I23: 洋室① | J23: 照明器具 | K23: スイッチ | L23: コンセント | M23: リモコン | O23: 住宅設備 | P23: 住宅設備②
C25: Panasonic | D25: Panasonic | K25: Panasonic | L25: Panasonic
C26: コスモ/ホタル | D26: コスモ | K26: コスモ/ホタル | L26: コスモ
C27: 2口 | D27: 2口 | K27: 2口 | L27: 2口
A28: 和室 | B28: 照明器具 | C28: スイッチ | D28: コンセント | E28: リモコン | I28: 洋室② | J28: 照明器具 | K28: スイッチ | L28: コンセント | M28: リモコン | O28: 住宅設備 | P28: 住宅設備②
C30: Panasonic | D30: Panasonic | K30: Panasonic | L30: Panasonic
C31: コスモ/ホタル | D31: コスモ | K31: コスモ/ホタル | L31: コスモ
C32: 2口 | D32: 2口 | K32: 2口 | L32: 2口
A33: 外部 | B33: 照明器具 | C33: スイッチ | D33: コンセント | J33: MEMO
J34: スイッチ 標準高さ | K34: H＝FL+1200 | L34: インターホン/リモコン 標準高さ | N34: H＝FL+1400
J35: コンセント 標準高さ | K35: H＝FL+250
J36: 冷蔵庫 標準高さ | K36: H＝FL+2000 | L36: もしくは、現状高さ 合わせ
D37: =見積内訳書!L19 -> 〒500-8388 | J37: =見積内訳書!L2 -> 浅野誠一郎 | L37: 様邸 改装工事 | O37: 担当 | P37: 作成日
D38: =見積内訳書!L20 -> 岐阜県岐阜市今嶺４丁目５−２０ | J38: 1階住宅設備/照明器具 | O38: =見積内訳書!L10 -> 0 | P38: =TODAY() -> 46216

Sheet ２階照明器具.住宅設備
A1: ● 2階 住宅設備/照明器具
A2: 階段 | B2: 照明器具 | C2: スイッチ | D2: コンセント | E2: リモコン | I2: トイレ | J2: 照明器具 | K2: スイッチ | L2: コンセント | M2: 給湯リモコン | O2: 住宅設備 | P2: 住宅設備②
B3: イメージ | C3: 取替 | R3: ←イメージ図/取替/既設
C4: Panasonic | D4: Panasonic | J4: Panasonic | K4: Panasonic | L4: Panasonic | O4: TOTO | R4: ←メーカー
C5: コスモ/ホタル | D5: コスモ | J5: ダウンライト/100 | K5: コスモ/ホタル | L5: コスモ | O5: ZJ | R5: ←シリーズ
C6: 2口 | D6: 2口 | J6: 昼白色 | K6: 2口 | L6: 2口 | O6: 別紙参照 | R6: ←品番/色
A7: ホール | B7: 照明器具 | C7: スイッチ | D7: コンセント | E7: リモコン | I7: 洗面室 | J7: 照明器具 | K7: スイッチ | L7: コンセント | M7: リモコン | O7: 住宅設備 | P7: 住宅設備②
C9: Panasonic | D9: Panasonic | J9: Panasonic | K9: Panasonic | L9: Panasonic | O9: Panasonic
C10: コスモ/ホタル | D10: コスモ | J10: ダウンライト/100 | K10: コスモ/ホタル | L10: コスモ | O10: C-ライン
C11: 2口 | D11: 2口 | J11: 昼白色 | K11: 2口 | L11: 2口 | O11: 別紙参照
A12: WIC | B12: 照明器具 | C12: スイッチ | D12: コンセント | E12: リモコン | I12: 居室 | J12: 照明器具 | K12: スイッチ | L12: コンセント | M12: リモコン
C14: Panasonic | D14: Panasonic | J14: Panasonic | K14: Panasonic | L14: Panasonic
C15: コスモ/ホタル | D15: コスモ | J15: ダウンライト/100 | K15: コスモ/ホタル | L15: コスモ
C16: 2口 | D16: 2口 | J16: 昼白色 | K16: 2口 | L16: 2口
A17: 廊下 | B17: 照明器具 | C17: スイッチ | D17: コンセント | E17: リモコン | I17: 居室 | J17: 照明器具 | K17: スイッチ | L17: コンセント | M17: リモコン
C20: Panasonic | D20: Panasonic | K20: Panasonic | L20: Panasonic
C21: コスモ/ホタル | D21: コスモ | K21: コスモ/ホタル | L21: コスモ
C22: 2口 | D22: 2口 | K22: 2口 | L22: 2口
A23: 洋室 | B23: 照明器具 | C23: スイッチ | D23: コンセント | E23: リモコン | I23: 居室 | J23: 照明器具 | K23: スイッチ | L23: コンセント | M23: リモコン
C25: Panasonic | D25: Panasonic | K25: Panasonic | L25: Panasonic
C26: コスモ/ホタル | D26: コスモ | K26: コスモ/ホタル | L26: コスモ
C27: 2口 | D27: 2口 | K27: 2口 | L27: 2口
A28: 洋室② | B28: 照明器具 | C28: スイッチ | D28: コンセント | E28: リモコン | I28: 居室 | J28: 照明器具 | K28: スイッチ | L28: コンセント | M28: リモコン
C30: Panasonic | D30: Panasonic | K30: Panasonic | L30: Panasonic
C31: コスモ/ホタル | D31: コスモ | K31: コスモ/ホタル | L31: コスモ
C32: 2口 | D32: 2口 | K32: 2口 | L32: 2口
A33: 他 | B33: 照明器具 | C33: スイッチ | D33: コンセント | J33: MEMO
J34: スイッチ 標準高さ | K34: H＝FL+1200 | L34: インターホン/リモコン 標準高さ | N34: H＝FL+1400
J35: コンセント 標準高さ | K35: H＝FL+250
J36: 冷蔵庫 標準高さ | K36: H＝FL+2000 | L36: もしくは、現状高さ 合わせ
D37: =見積内訳書!L19 -> 〒500-8388 | J37: =見積内訳書!L2 -> 浅野誠一郎 | L37: 様邸 改装工事 | O37: 担当 | P37: 作成日
D38: =見積内訳書!L20 -> 岐阜県岐阜市今嶺４丁目５−２０ | J38: 2階住宅設備/照明器具 | O38: =見積内訳書!L10 -> 0 | P38: =TODAY() -> 46216

Sheet データ
B2: 個
B3: 本
B4: 枚
B5: 梱
B6: ｍ
B7: ㎡
B8: ㎥
B9: 式
B10: 箇所
B11: セット
B12: 台
B13: 段
... B15: 呼称
